Workbook

Sheet Presupuesto por Partidas
A1: PRESUPUESTO POR PARTIDAS
B2: Partida y Fase | C2: Actividad | D2: Cantidad | E2: Unidad | F2: Costo unitario (S/) | G2: Subtotal (S/) | H2: Descripcion
B3: FASE 1: ANÁLISIS DE REQUISITOS | C3: Levantamiento y reconocimiento del problema | D3: 24 | E3: hora | F3: 57 | G3: =D3*F3 -> 1368 | H3: Necesidades de conductores, acompañantes y supervisores
B4: FASE 1: ANÁLISIS DE REQUISITOS | C4: Entrevistas y recopilación de información | D4: 20 | E4: hora | F4: 53 | G4: =D4*F4 -> 1060 | H4: Entrevistas con usuarios y responsables
B5: FASE 1: ANÁLISIS DE REQUISITOS | C5: Definición de objetivos y alcance | D5: 12 | E5: hora | F5: 57 | G5: =D5*F5 -> 684 | H5: Objetivo general, específicos, límites y supuestos
B6: FASE 1: ANÁLISIS DE REQUISITOS | C6: Identificación de stakeholders | D6: 10 | E6: hora | F6: 53 | G6: =D6*F6 -> 530 | H6: Usuarios, administrador, supervisor y soporte
B7: FASE 1: ANÁLISIS DE REQUISITOS | C7: Análisis de requisitos funcionales móvil | D7: 24 | E7: hora | F7: 57 | G7: =D7*F7 -> 1368 | H7: RF-M01 a RF-M11
B8: FASE 1: ANÁLISIS DE REQUISITOS | C8: Análisis de requisitos funcionales web | D8: 18 | E8: hora | F8: 57 | G8: =D8*F8 -> 1026 | H8: RF-W01 a RF-W06
B9: FASE 1: ANÁLISIS DE REQUISITOS | C9: Requisitos no funcionales y restricciones | D9: 12 | E9: hora | F9: 57 | G9: =D9*F9 -> 684 | H9: Rendimiento, seguridad, disponibilidad y conectividad
B10: FASE 1: ANÁLISIS DE REQUISITOS | C10: Modelado inicial de datos | D10: 14 | E10: hora | F10: 57 | G10: =D10*F10 -> 798 | H10: Usuarios, rutas, viajes, coordenadas e incidentes
B11: FASE 1: ANÁLISIS DE REQUISITOS | C11: Documentación y validación de requisitos | D11: 12 | E11: hora | F11: 57 | G11: =D11*F11 -> 684 | H11: Especificación, revisión y aprobación
B12: FASE 1: ANÁLISIS DE REQUISITOS | C12: Taller de validación con usuarios | D12: 1 | E12: lote | F12: 494 | G12: =D12*F12 -> 494 | H12: Sesión de revisión y validación de requerimientos
B13: FASE 1: ANÁLISIS DE REQUISITOS | C13: Internet y servicios de trabajo | D13: 1 | E13: lote | F13: 2960 | G13: =D13*F13 -> 2960 | H13: Conectividad y gastos operativos de la fase
A14: TOTAL | B14: FASE 1: ANÁLISIS DE REQUISITOS | G14: =SUM(G3:G13) -> 11656
B15: FASE 2: DISEÑO DEL PROYECTO | C15: Arquitectura general móvil + backend + web | D15: 24 | E15: hora | F15: 44 | G15: =D15*F15 -> 1056 | H15: Flutter, API REST, Spring Boot y arquitectura web
B16: FASE 2: DISEÑO DEL PROYECTO | C16: Diseño UI/UX móvil | D16: 32 | E16: hora | F16: 50 | G16: =D16*F16 -> 1600 | H16: Login, rutas, viaje, alertas y acompañamiento
B17: FASE 2: DISEÑO DEL PROYECTO | C17: Diseño de interfaz web administrativa | D17: 24 | E17: hora | F17: 52 | G17: =D17*F17 -> 1248 | H17: Usuarios, rutas, tramos, incidentes y reportes
B18: FASE 2: DISEÑO DEL PROYECTO | C18: Wireframes y prototipos navegables | D18: 20 | E18: hora | F18: 45 | G18: =D18*F18 -> 900 | H18: Flujos principales y validación visual
B19: FASE 2: DISEÑO DEL PROYECTO | C19: Diseño de base de datos | D19: 18 | E19: hora | F19: 44 | G19: =D19*F19 -> 792 | H19: Modelo entidad-relación, tablas y relaciones
B20: FASE 2: DISEÑO DEL PROYECTO | C20: Diseño de seguridad y botón de pánico | D20: 12 | E20: hora | F20: 44 | G20: =D20*F20 -> 528 | H20: Acceso, roles, alertas y control
B21: FASE 2: DISEÑO DEL PROYECTO | C21: Diseño de API y contratos | D21: 14 | E21: hora | F21: 44 | G21: =D21*F21 -> 616 | H21: Endpoints, payloads y respuestas
B22: FASE 2: DISEÑO DEL PROYECTO | C22: Diseño de navegación y experiencia GPS | D22: 12 | E22: hora | F22: 40 | G22: =D22*F22 -> 480 | H22: Flujos de ubicación, rutas y seguimiento
B23: FASE 2: DISEÑO DEL PROYECTO | C23: Documentación y revisión del diseño | D23: 10 | E23: hora | F23: 40 | G23: =D23*F23 -> 400 | H23: Especificaciones técnicas y aprobación
B24: FASE 2: DISEÑO DEL PROYECTO | C24: Recursos de diseño e impresión | D24: 1 | E24: lote | F24: 1756 | G24: =D24*F24 -> 1756 | H24: Materiales, impresiones y evidencias
A25: TOTAL | B25: FASE 2: DISEÑO DEL PROYECTO | G25: =SUM(G15:G24) -> 9376
B26: FASE 3: IMPLEMENTACIÓN Y CODIFICACIÓN | C26: Configuración del proyecto Flutter | D26: 20 | E26: hora | F26: 58 | G26: =D26*F26 -> 1160 | H26: Estructura base, dependencias y configuración
B27: FASE 3: IMPLEMENTACIÓN Y CODIFICACIÓN | C27: Desarrollo Login / Registro | D27: 24 | E27: hora | F27: 48 | G27: =D27*F27 -> 1152 | H27: RF-M01
B28: FASE 3: IMPLEMENTACIÓN Y CODIFICACIÓN | C28: Desarrollo selección de ruta | D28: 28 | E28: hora | F28: 48 | G28: =D28*F28 -> 1344 | H28: RF-M03
B29: FASE 3: IMPLEMENTACIÓN Y CODIFICACIÓN | C29: GPS y captura de coordenadas | D29: 40 | E29: hora | F29: 41 | G29: =D29*F29 -> 1640 | H29: RF-M04
B30: FASE 3: IMPLEMENTACIÓN Y CODIFICACIÓN | C30: Viaje activo y monitoreo | D30: 36 | E30: hora | F30: 41 | G30: =D30*F30 -> 1476 | H30: RF-M02 y RF-M08
B31: FASE 3: IMPLEMENTACIÓN Y CODIFICACIÓN | C31: Alertas e incidentes | D31: 28 | E31: hora | F31: 48 | G31: =D31*F31 -> 1344 | H31: RF-M06
B32: FASE 3: IMPLEMENTACIÓN Y CODIFICACIÓN | C32: Botón de pánico | D32: 20 | E32: hora | F32: 41 | G32: =D32*F32 -> 820 | H32: RF-M07
B33: FASE 3: IMPLEMENTACIÓN Y CODIFICACIÓN | C33: Acompañamiento preventivo | D33: 28 | E33: hora | F33: 41 | G33: =D33*F33 -> 1148 | H33: RF-M08 y RF-M09
B34: FASE 3: IMPLEMENTACIÓN Y CODIFICACIÓN | C34: Historial y finalización del viaje | D34: 20 | E34: hora | F34: 48 | G34: =D34*F34 -> 960 | H34: RF-M10 y RF-M11
B35: FASE 3: IMPLEMENTACIÓN Y CODIFICACIÓN | C35: Backend Spring Boot y API REST | D35: 50 | E35: hora | F35: 41 | G35: =D35*F35 -> 2050 | H35: Usuarios, rutas, viajes e incidentes
B36: FASE 3: IMPLEMENTACIÓN Y CODIFICACIÓN | C36: Base de datos e integración | D36: 36 | E36: hora | F36: 45 | G36: =D36*F36 -> 1620 | H36: Persistencia, consultas y relaciones
B37: FASE 3: IMPLEMENTACIÓN Y CODIFICACIÓN | C37: Módulo web administrativo | D37: 44 | E37: hora | F37: 45 | G37: =D37*F37 -> 1980 | H37: Gestión de usuarios, rutas e incidentes
... B40: FASE 3: IMPLEMENTACIÓN Y CODIFICACIÓN | C40: Servidor, hosting y conectividad | D40: 1 | E40: lote | F40: 3473 | G40: =D40*F40 -> 3473 | H40: Ambiente de integración y despliegue
A41: TOTAL | B41: FASE 3: IMPLEMENTACIÓN Y CODIFICACIÓN | G41: =SUM(G26:G40) -> 22687
B42: FASE 4: PRUEBAS Y VALIDACIÓN | C42: Pruebas funcionales móviles | D42: 28 | E42: hora | F42: 45 | G42: =D42*F42 -> 1260 | H42: Login, rutas, GPS y alertas
...

Sheet Hoja1

Sheet Presupuesto
A1: PRESUPUESTO DEL PROYECTO
A2: Fase | B2: Descripción | C2: Presupuesto (S/) | D2: % del total | E2: Recursos principales | F2: Entregable
A3: Fase 1 | B3: Análisis de Requisitos | C3: ='Presupuesto por Partidas'!G14 -> 11656 | D3: =C3/$C$10 -> 0.17155203 | E3: RF/RNF validados | F3: Entrevistas, análisis y documentación
A4: Fase 2 | B4: Diseño del Proyecto | C4: ='Presupuesto por Partidas'!G25 -> 9376 | D4: =C4/$C$10 -> 0.13799518 | E4: Interfaces web y móvil | F4: UI/UX, BD, API y seguridad
A5: Fase 3 | B5: Implementación y Codificación | C5: ='Presupuesto por Partidas'!G41 -> 22687 | D5: =C5/$C$10 -> 0.33390537 | E5: Integración móvil-backend-web | F5: Flutter, Spring Boot, BD, mapas y despliegue
A6: Fase 4 | B6: Pruebas y Validación | C6: ='Presupuesto por Partidas'!G51 -> 8664 | D6: =C6/$C$10 -> 0.12751603 | E6: Validación funcional | F6: Pruebas funcionales, integración, seguridad y piloto
A7: Fase 5 | B7: Mantenimiento y Soporte | C7: ='Presupuesto por Partidas'!G60 -> 5197 | D7: =C7/$C$10 -> 0.076489012 | E7: Versión final y documentación | F7: Correcciones, soporte, hosting y capacitación
A8: SUBTOTAL (sin IGV) | C8: =SUM(C3:C7) -> 57580
A9: IGV (18%) | C9: =C8*0.18 -> 10364.4
A10: TOTAL CON IGV | C10: =SUM(C8,C9) -> 67944.4 | D10: =C10/$C$10 -> 1

Sheet Hoja de Recursos
A1: HOJA DE RECURSOS
B2: Recurso | C2: Categoría | D2: Unidad | E2: Cantidad | F2: Costo unitario (S/) | G2: Costo total (S/) | H2: Fase | I2: Responsabilidad / uso
B3: Analista de requisitos | C3: Humano | D3: hora | E3: 90 | F3: 60 | G3: =E3*F3 -> 5400 | H3: Fase 1 | I3: Levantamiento, análisis y validación de requisitos
B4: Diseñador UI/UX | C4: Humano | D4: hora | E4: 80 | F4: 65 | G4: =E4*F4 -> 5200 | H4: Fases 1–2 | I4: Flujos, wireframes y diseño de interfaces
B5: Arquitecto / analista técnico | C5: Humano | D5: hora | E5: 45 | F5: 80 | G5: =E5*F5 -> 3600 | H5: Fases 1–3 | I5: Arquitectura y especificaciones
B6: Desarrollador Flutter | C6: Humano | D6: hora | E6: 125 | F6: 75 | G6: =E6*F6 -> 9375 | H6: Fases 2–3 | I6: Desarrollo móvil y GPS
B7: Desarrollador Spring Boot | C7: Humano | D7: hora | E7: 90 | F7: 85 | G7: =E7*F7 -> 7650 | H7: Fases 2–3 | I7: API REST, lógica e integración
B8: Administrador / desarrollador BD | C8: Humano | D8: hora | E8: 65 | F8: 70 | G8: =E8*F8 -> 4550 | H8: Fases 1–3 | I8: Modelo, tablas y persistencia
B9: Desarrollador web | C9: Humano | D9: hora | E9: 55 | F9: 75 | G9: =E9*F9 -> 4125 | H9: Fases 2–3 | I9: Panel administrativo web
B10: QA / Tester | C10: Humano | D10: hora | E10: 65 | F10: 60 | G10: =E10*F10 -> 3900 | H10: Fase 4 | I10: Pruebas y validación
B11: Soporte y mantenimiento | C11: Humano | D11: hora | E11: 45 | F11: 55 | G11: =E11*F11 -> 2475 | H11: Fase 5 | I11: Correcciones y soporte
B12: Computadora de desarrollo | C12: Equipo | D12: mes | E12: 4 | F12: 250 | G12: =E12*F12 -> 1000 | H12: Fases 1–5 | I12: IDE, Flutter, Java/Spring Boot y documentación
B13: Smartphones de prueba | C13: Equipo | D13: mes | E13: 4 | F13: 800 | G13: =E13*F13 -> 3200 | H13: Fases 3–4 | I13: GPS, sensores, alertas y batería
B14: Internet | C14: Servicio | D14: mes | E14: 4 | F14: 180 | G14: =E14*F14 -> 720 | H14: Fases 1–5 | I14: Conectividad de desarrollo y pruebas
... B23: Contingencia operativa del proyecto | C23: Reserva | D23: lote | E23: 1 | F23: 625 | G23: =E23*F23 -> 625 | H23: Fases 1–5 | I23: Margen para imprevistos y ajustes no previstos
A24: SUBTOTAL (sin IGV) | G24: =SUM(G3:G23) -> 57580
A25: IGV (18%) | G25: =G24*0.18 -> 10364.4
A26: TOTAL CON IGV | G26: =SUM(G24:G25) -> 67944.4
